# 随笔

### 1. promise

> 在`promise.then()`中若代码有异常，不会报错，而报错在`catch()`中

```js
function fn(n) {
    return new Promise((resolve, reject) => {
        if (n === 1) {
            resolve(1);
        } else {
            reject(2);
        }
    })
}

fn(1).then(res => {
    console.log("成功");
    // "test" is not definde，从这里断开进入失败回调
    console.log(test);
}).catch(err => {
    console.log("失败");
    console.log(err);
});
```

<script>

function fn(n) {
    return new Promise((resolve, reject) => {
        if (n === 1) {
            resolve(1);
        } else {
            reject(2);
        }
    })
}
console.group("promise");
fn(1).then(res => {
    console.log("成功");
    console.log(test);
}).catch(err => {
    console.log("失败");
    console.log(err);
});
console.groupEnd();

</script>


### 2. 局部刷新